2020/12/20 18:40:33 : Traceback (most recent call last):
  File "/var/www/python/cartmigration/controllers/migration.py", line 665, in storage_data
    getattr(self.get_source_cart(), 'finish_storage_data')()
  File "/var/www/python/cartmigration/models/basecart.py", line 3930, in finish_storage_data
    folder_upload = self.get_folder_upload(self._migration_id)
  File "/var/www/python/cartmigration/models/basecart.py", line 3942, in get_folder_upload
    folder_upload = root_path + '/' + DIR_UPLOAD + '/' + get_config_ini('src', 'file', file = 'test.ini')
TypeError: can only concatenate str (not "NoneType") to str

2020/12/20 18:41:09 : Error Connecting:HTTPSConnectionPool(host='shopifieah.myshopify.com', port=443): Max retries exceeded with url: /admin/api/2020-10/products/6151540113603.json (Caused by NewConnectionError('<urllib3.connection.VerifiedHTTPSConnection object at 0x7fba2afaed90>: Failed to establish a new connection: [Errno -3] Temporary failure in name resolution')) : False
2020/12/20 18:42:35 : Error Connecting:HTTPSConnectionPool(host='shopifieah.myshopify.com', port=443): Max retries exceeded with url: /admin/api/2020-10/custom_collections.json (Caused by NewConnectionError('<urllib3.connection.VerifiedHTTPSConnection object at 0x7fba2b005090>: Failed to establish a new connection: [Errno -3] Temporary failure in name resolution')) : False
2020/12/20 18:44:12 : Traceback (most recent call last):
  File "/var/www/python/bootstrap.py", line 20, in <module>
    getattr(controller, action_name)(data)
  File "/var/www/python/cartmigration/controllers/migration.py", line 86, in start
    self.run()
  File "/var/www/python/cartmigration/controllers/migration.py", line 132, in run
    result = getattr(self, action)()
  File "/var/www/python/cartmigration/controllers/migration.py", line 1377, in finish_migration
    self.notify_error(entity)
  File "/var/www/python/cartmigration/controllers/migration.py", line 1403, in notify_error
    getattr(self.get_router(), 'create_demo_error')(self._notice)
  File "/var/www/python/cartmigration/models/migration.py", line 310, in create_demo_error
    'user_id': migration['user_id'],
KeyError: 'user_id'

